
(0.000) 
            SELECT name, type FROM sqlite_master
            WHERE type in ('table', 'view') AND NOT name='sqlite_sequence'
            ORDER BY name; args=None
(0.000) SELECT "django_migrations"."app", "django_migrations"."name" FROM "django_migrations"; args=()
Daphne running, listening on 127.0.0.1:8000
(0.000) 
            SELECT name, type FROM sqlite_master
            WHERE type in ('table', 'view') AND NOT name='sqlite_sequence'
            ORDER BY name; args=None
(0.000) SELECT "django_migrations"."app", "django_migrations"."name" FROM "django_migrations"; args=()
Daphne running, listening on 127.0.0.1:8000
(0.000) SELECT COUNT(*) AS "__count" FROM "blog_post"; args=()
(0.000) SELECT "blog_post"."id", "blog_post"."title", "blog_post"."content", "blog_post"."date_posted", "blog_post"."date_expired", "blog_post"."author_id", "blog_post"."fileAttachment", "blog_post"."imageAttachment" FROM "blog_post" ORDER BY "blog_post"."date_posted" DESC  LIMIT 1; args=()
(0.000) SELECT "blog_post"."id", "blog_post"."title", "blog_post"."content", "blog_post"."date_posted", "blog_post"."date_expired", "blog_post"."author_id", "blog_post"."fileAttachment", "blog_post"."imageAttachment" FROM "blog_post" ORDER BY "blog_post"."date_posted" DESC  LIMIT 1; args=()
Exception while resolving variable 'title' in template 'blog/home.html'.
Traceback (most recent call last):
  File "/usr/lib/python3.7/site-packages/django/template/base.py", line 829, in _resolve_lookup
    current = current[bit]
  File "/usr/lib/python3.7/site-packages/django/template/context.py", line 83, in __getitem__
    raise KeyError(key)
KeyError: 'title'

During handling of the above exception, another exception occurred:

Traceback (most recent call last):
  File "/usr/lib/python3.7/site-packages/django/template/base.py", line 835, in _resolve_lookup
    if isinstance(current, BaseContext) and getattr(type(current), bit):
AttributeError: type object 'RequestContext' has no attribute 'title'

During handling of the above exception, another exception occurred:

Traceback (most recent call last):
  File "/usr/lib/python3.7/site-packages/django/template/base.py", line 843, in _resolve_lookup
    current = current[int(bit)]
ValueError: invalid literal for int() with base 10: 'title'

During handling of the above exception, another exception occurred:

Traceback (most recent call last):
  File "/usr/lib/python3.7/site-packages/django/template/base.py", line 850, in _resolve_lookup
    (bit, current))  # missing attribute
django.template.base.VariableDoesNotExist: Failed lookup for key [title] in [{'True': True, 'False': False, 'None': None}, {'csrf_token': <SimpleLazyObject: <function csrf.<locals>._get_val at 0x7ff4f74450d0>>, 'request': <AsgiRequest: GET '/'>, 'user': <SimpleLazyObject: <function AuthenticationMiddleware.process_request.<locals>.<lambda> at 0x7ff4f747e488>>, 'perms': <django.contrib.auth.context_processors.PermWrapper object at 0x7ff4f6beb940>, 'messages': <django.contrib.messages.storage.fallback.FallbackStorage object at 0x7ff4f7421b38>, 'DEFAULT_MESSAGE_LEVELS': {'DEBUG': 10, 'INFO': 20, 'SUCCESS': 25, 'WARNING': 30, 'ERROR': 40}}, {}, {'paginator': <django.core.paginator.Paginator object at 0x7ff4f7438f98>, 'page_obj': <Page 1 of 1>, 'is_paginated': False, 'object_list': <QuerySet [<Post: First Announcement>]>, 'posts': <QuerySet [<Post: First Announcement>]>, 'view': <blog.views.PostListView object at 0x7ff4f7421a20>}]
(0.000) SELECT "django_session"."session_key", "django_session"."session_data", "django_session"."expire_date" FROM "django_session" WHERE ("django_session"."expire_date" > '2019-04-24 15:16:07.931295' AND "django_session"."session_key" = 'bxpt7g6j9sufe1f4vdvfcmhqcijixtqx'); args=('2019-04-24 15:16:07.931295', 'bxpt7g6j9sufe1f4vdvfcmhqcijixtqx')
(0.000) SELECT "users_user"."id", "users_user"."password", "users_user"."last_login", "users_user"."is_superuser", "users_user"."username", "users_user"."first_name", "users_user"."last_name", "users_user"."email", "users_user"."is_staff", "users_user"."is_active", "users_user"."date_joined", "users_user"."phone_number", "users_user"."role", "users_user"."institution_id" FROM "users_user" WHERE "users_user"."id" = 1; args=(1,)
(0.000) SELECT "institutions_institution"."id", "institutions_institution"."name", "institutions_institution"."abbreviation", "institutions_institution"."city_id", "institutions_institution"."met", "institutions_institution"."moc", "institutions_institution"."ethics", "institutions_institution"."status_request", "institutions_institution"."is_private", "institutions_institution"."ri_1_tools", "institutions_institution"."general", "institutions_institution"."role", "institutions_institution"."type_of_inst", "institutions_institution"."student_count", "institutions_institution"."staff_count", "institutions_institution"."internet_access", "institutions_institution"."online", "institutions_institution"."guest_lectures", "institutions_institution"."environment", "institutions_institution"."focus_pst", "institutions_institution"."further", "institutions_institution"."school_size", "institutions_institution"."community_size", "institutions_institution"."girl_ratio", "institutions_institution"."qualifications", "institutions_institution"."percent_indigenous", "institutions_institution"."age" FROM "institutions_institution" WHERE "institutions_institution"."id" = 1; args=(1,)
(0.000) SELECT "blog_post"."id", "blog_post"."title", "blog_post"."content", "blog_post"."date_posted", "blog_post"."date_expired", "blog_post"."author_id", "blog_post"."fileAttachment", "blog_post"."imageAttachment" FROM "blog_post" ORDER BY "blog_post"."date_posted" DESC  LIMIT 1; args=()
(0.000) SELECT "users_user"."id", "users_user"."password", "users_user"."last_login", "users_user"."is_superuser", "users_user"."username", "users_user"."first_name", "users_user"."last_name", "users_user"."email", "users_user"."is_staff", "users_user"."is_active", "users_user"."date_joined", "users_user"."phone_number", "users_user"."role", "users_user"."institution_id" FROM "users_user" WHERE "users_user"."id" = 1; args=(1,)
[mHTTP GET / 200 [0.04, 127.0.0.1:56636][0m
(0.000) SELECT COUNT(*) AS "__count" FROM "blog_post"; args=()
(0.000) SELECT "blog_post"."id", "blog_post"."title", "blog_post"."content", "blog_post"."date_posted", "blog_post"."date_expired", "blog_post"."author_id", "blog_post"."fileAttachment", "blog_post"."imageAttachment" FROM "blog_post" ORDER BY "blog_post"."date_posted" DESC  LIMIT 1; args=()
(0.000) SELECT "blog_post"."id", "blog_post"."title", "blog_post"."content", "blog_post"."date_posted", "blog_post"."date_expired", "blog_post"."author_id", "blog_post"."fileAttachment", "blog_post"."imageAttachment" FROM "blog_post" ORDER BY "blog_post"."date_posted" DESC  LIMIT 1; args=()
Exception while resolving variable 'title' in template 'blog/home.html'.
Traceback (most recent call last):
  File "/usr/lib/python3.7/site-packages/django/template/base.py", line 829, in _resolve_lookup
    current = current[bit]
  File "/usr/lib/python3.7/site-packages/django/template/context.py", line 83, in __getitem__
    raise KeyError(key)
KeyError: 'title'

During handling of the above exception, another exception occurred:

Traceback (most recent call last):
  File "/usr/lib/python3.7/site-packages/django/template/base.py", line 835, in _resolve_lookup
    if isinstance(current, BaseContext) and getattr(type(current), bit):
AttributeError: type object 'RequestContext' has no attribute 'title'

During handling of the above exception, another exception occurred:

Traceback (most recent call last):
  File "/usr/lib/python3.7/site-packages/django/template/base.py", line 843, in _resolve_lookup
    current = current[int(bit)]
ValueError: invalid literal for int() with base 10: 'title'

During handling of the above exception, another exception occurred:

Traceback (most recent call last):
  File "/usr/lib/python3.7/site-packages/django/template/base.py", line 850, in _resolve_lookup
    (bit, current))  # missing attribute
django.template.base.VariableDoesNotExist: Failed lookup for key [title] in [{'True': True, 'False': False, 'None': None}, {'csrf_token': <SimpleLazyObject: <function csrf.<locals>._get_val at 0x7ff4f6bb9c80>>, 'request': <AsgiRequest: GET '/'>, 'user': <SimpleLazyObject: <function AuthenticationMiddleware.process_request.<locals>.<lambda> at 0x7ff4f6aa8378>>, 'perms': <django.contrib.auth.context_processors.PermWrapper object at 0x7ff4f6bda128>, 'messages': <django.contrib.messages.storage.fallback.FallbackStorage object at 0x7ff4f6be4ac8>, 'DEFAULT_MESSAGE_LEVELS': {'DEBUG': 10, 'INFO': 20, 'SUCCESS': 25, 'WARNING': 30, 'ERROR': 40}}, {}, {'paginator': <django.core.paginator.Paginator object at 0x7ff4f6be4b70>, 'page_obj': <Page 1 of 1>, 'is_paginated': False, 'object_list': <QuerySet [<Post: First Announcement>]>, 'posts': <QuerySet [<Post: First Announcement>]>, 'view': <blog.views.PostListView object at 0x7ff4f6be4cc0>}]
(0.000) SELECT "django_session"."session_key", "django_session"."session_data", "django_session"."expire_date" FROM "django_session" WHERE ("django_session"."expire_date" > '2019-04-24 15:16:13.049720' AND "django_session"."session_key" = 'bxpt7g6j9sufe1f4vdvfcmhqcijixtqx'); args=('2019-04-24 15:16:13.049720', 'bxpt7g6j9sufe1f4vdvfcmhqcijixtqx')
(0.000) SELECT "users_user"."id", "users_user"."password", "users_user"."last_login", "users_user"."is_superuser", "users_user"."username", "users_user"."first_name", "users_user"."last_name", "users_user"."email", "users_user"."is_staff", "users_user"."is_active", "users_user"."date_joined", "users_user"."phone_number", "users_user"."role", "users_user"."institution_id" FROM "users_user" WHERE "users_user"."id" = 1; args=(1,)
(0.000) SELECT "institutions_institution"."id", "institutions_institution"."name", "institutions_institution"."abbreviation", "institutions_institution"."city_id", "institutions_institution"."met", "institutions_institution"."moc", "institutions_institution"."ethics", "institutions_institution"."status_request", "institutions_institution"."is_private", "institutions_institution"."ri_1_tools", "institutions_institution"."general", "institutions_institution"."role", "institutions_institution"."type_of_inst", "institutions_institution"."student_count", "institutions_institution"."staff_count", "institutions_institution"."internet_access", "institutions_institution"."online", "institutions_institution"."guest_lectures", "institutions_institution"."environment", "institutions_institution"."focus_pst", "institutions_institution"."further", "institutions_institution"."school_size", "institutions_institution"."community_size", "institutions_institution"."girl_ratio", "institutions_institution"."qualifications", "institutions_institution"."percent_indigenous", "institutions_institution"."age" FROM "institutions_institution" WHERE "institutions_institution"."id" = 1; args=(1,)
(0.000) SELECT "blog_post"."id", "blog_post"."title", "blog_post"."content", "blog_post"."date_posted", "blog_post"."date_expired", "blog_post"."author_id", "blog_post"."fileAttachment", "blog_post"."imageAttachment" FROM "blog_post" ORDER BY "blog_post"."date_posted" DESC  LIMIT 1; args=()
(0.000) SELECT "users_user"."id", "users_user"."password", "users_user"."last_login", "users_user"."is_superuser", "users_user"."username", "users_user"."first_name", "users_user"."last_name", "users_user"."email", "users_user"."is_staff", "users_user"."is_active", "users_user"."date_joined", "users_user"."phone_number", "users_user"."role", "users_user"."institution_id" FROM "users_user" WHERE "users_user"."id" = 1; args=(1,)
[mHTTP GET / 200 [0.01, 127.0.0.1:56636][0m
(0.000) SELECT "django_session"."session_key", "django_session"."session_data", "django_session"."expire_date" FROM "django_session" WHERE ("django_session"."expire_date" > '2019-04-24 15:16:13.836300' AND "django_session"."session_key" = 'bxpt7g6j9sufe1f4vdvfcmhqcijixtqx'); args=('2019-04-24 15:16:13.836300', 'bxpt7g6j9sufe1f4vdvfcmhqcijixtqx')
(0.000) SELECT "users_user"."id", "users_user"."password", "users_user"."last_login", "users_user"."is_superuser", "users_user"."username", "users_user"."first_name", "users_user"."last_name", "users_user"."email", "users_user"."is_staff", "users_user"."is_active", "users_user"."date_joined", "users_user"."phone_number", "users_user"."role", "users_user"."institution_id" FROM "users_user" WHERE "users_user"."id" = 1; args=(1,)
(0.000) SELECT "dynamicforms_dynamicforms"."id", "dynamicforms_dynamicforms"."creator_id", "dynamicforms_dynamicforms"."title", "dynamicforms_dynamicforms"."is_active", "dynamicforms_dynamicforms"."creation_time", "dynamicforms_dynamicforms"."expiry_date" FROM "dynamicforms_dynamicforms"  LIMIT 21; args=()
Exception while resolving variable 'title' in template 'dynamicforms/home.html'.
Traceback (most recent call last):
  File "/usr/lib/python3.7/site-packages/django/template/base.py", line 829, in _resolve_lookup
    current = current[bit]
  File "/usr/lib/python3.7/site-packages/django/template/context.py", line 83, in __getitem__
    raise KeyError(key)
KeyError: 'title'

During handling of the above exception, another exception occurred:

Traceback (most recent call last):
  File "/usr/lib/python3.7/site-packages/django/template/base.py", line 835, in _resolve_lookup
    if isinstance(current, BaseContext) and getattr(type(current), bit):
AttributeError: type object 'RequestContext' has no attribute 'title'

During handling of the above exception, another exception occurred:

Traceback (most recent call last):
  File "/usr/lib/python3.7/site-packages/django/template/base.py", line 843, in _resolve_lookup
    current = current[int(bit)]
ValueError: invalid literal for int() with base 10: 'title'

During handling of the above exception, another exception occurred:

Traceback (most recent call last):
  File "/usr/lib/python3.7/site-packages/django/template/base.py", line 850, in _resolve_lookup
    (bit, current))  # missing attribute
django.template.base.VariableDoesNotExist: Failed lookup for key [title] in [{'True': True, 'False': False, 'None': None}, {'csrf_token': <SimpleLazyObject: <function csrf.<locals>._get_val at 0x7ff4f6bb9510>>, 'request': <AsgiRequest: GET '/forms/'>, 'user': <SimpleLazyObject: <User: admin>>, 'perms': <django.contrib.auth.context_processors.PermWrapper object at 0x7ff4f6bcac88>, 'messages': <django.contrib.messages.storage.fallback.FallbackStorage object at 0x7ff4f6be4278>, 'DEFAULT_MESSAGE_LEVELS': {'DEBUG': 10, 'INFO': 20, 'SUCCESS': 25, 'WARNING': 30, 'ERROR': 40}}, {}, {'forms': <QuerySet [<DynamicForms: Form 1>]>}]
(0.000) SELECT "institutions_institution"."id", "institutions_institution"."name", "institutions_institution"."abbreviation", "institutions_institution"."city_id", "institutions_institution"."met", "institutions_institution"."moc", "institutions_institution"."ethics", "institutions_institution"."status_request", "institutions_institution"."is_private", "institutions_institution"."ri_1_tools", "institutions_institution"."general", "institutions_institution"."role", "institutions_institution"."type_of_inst", "institutions_institution"."student_count", "institutions_institution"."staff_count", "institutions_institution"."internet_access", "institutions_institution"."online", "institutions_institution"."guest_lectures", "institutions_institution"."environment", "institutions_institution"."focus_pst", "institutions_institution"."further", "institutions_institution"."school_size", "institutions_institution"."community_size", "institutions_institution"."girl_ratio", "institutions_institution"."qualifications", "institutions_institution"."percent_indigenous", "institutions_institution"."age" FROM "institutions_institution" WHERE "institutions_institution"."id" = 1; args=(1,)
(0.000) SELECT "dynamicforms_dynamicforms"."id", "dynamicforms_dynamicforms"."creator_id", "dynamicforms_dynamicforms"."title", "dynamicforms_dynamicforms"."is_active", "dynamicforms_dynamicforms"."creation_time", "dynamicforms_dynamicforms"."expiry_date" FROM "dynamicforms_dynamicforms"; args=()
[mHTTP GET /forms/ 200 [0.01, 127.0.0.1:56636][0m
[mHTTP GET /static/download_icon_no_watermark.png 200 [0.00, 127.0.0.1:56636][0m
(0.000) SELECT "django_session"."session_key", "django_session"."session_data", "django_session"."expire_date" FROM "django_session" WHERE ("django_session"."expire_date" > '2019-04-24 15:16:23.232380' AND "django_session"."session_key" = 'bxpt7g6j9sufe1f4vdvfcmhqcijixtqx'); args=('2019-04-24 15:16:23.232380', 'bxpt7g6j9sufe1f4vdvfcmhqcijixtqx')
(0.000) SELECT "users_user"."id", "users_user"."password", "users_user"."last_login", "users_user"."is_superuser", "users_user"."username", "users_user"."first_name", "users_user"."last_name", "users_user"."email", "users_user"."is_staff", "users_user"."is_active", "users_user"."date_joined", "users_user"."phone_number", "users_user"."role", "users_user"."institution_id" FROM "users_user" WHERE "users_user"."id" = 1; args=(1,)
(0.000) SELECT "dynamicforms_dynamicforms"."id", "dynamicforms_dynamicforms"."creator_id", "dynamicforms_dynamicforms"."title", "dynamicforms_dynamicforms"."is_active", "dynamicforms_dynamicforms"."creation_time", "dynamicforms_dynamicforms"."expiry_date" FROM "dynamicforms_dynamicforms"  LIMIT 21; args=()
Exception while resolving variable 'title' in template 'dynamicforms/home.html'.
Traceback (most recent call last):
  File "/usr/lib/python3.7/site-packages/django/template/base.py", line 829, in _resolve_lookup
    current = current[bit]
  File "/usr/lib/python3.7/site-packages/django/template/context.py", line 83, in __getitem__
    raise KeyError(key)
KeyError: 'title'

During handling of the above exception, another exception occurred:

Traceback (most recent call last):
  File "/usr/lib/python3.7/site-packages/django/template/base.py", line 835, in _resolve_lookup
    if isinstance(current, BaseContext) and getattr(type(current), bit):
AttributeError: type object 'RequestContext' has no attribute 'title'

During handling of the above exception, another exception occurred:

Traceback (most recent call last):
  File "/usr/lib/python3.7/site-packages/django/template/base.py", line 843, in _resolve_lookup
    current = current[int(bit)]
ValueError: invalid literal for int() with base 10: 'title'

During handling of the above exception, another exception occurred:

Traceback (most recent call last):
  File "/usr/lib/python3.7/site-packages/django/template/base.py", line 850, in _resolve_lookup
    (bit, current))  # missing attribute
django.template.base.VariableDoesNotExist: Failed lookup for key [title] in [{'True': True, 'False': False, 'None': None}, {'csrf_token': <SimpleLazyObject: <function csrf.<locals>._get_val at 0x7ff4f74450d0>>, 'request': <AsgiRequest: GET '/forms/?download=1'>, 'user': <SimpleLazyObject: <User: admin>>, 'perms': <django.contrib.auth.context_processors.PermWrapper object at 0x7ff4f6bdfac8>, 'messages': <django.contrib.messages.storage.fallback.FallbackStorage object at 0x7ff4f6bdf6a0>, 'DEFAULT_MESSAGE_LEVELS': {'DEBUG': 10, 'INFO': 20, 'SUCCESS': 25, 'WARNING': 30, 'ERROR': 40}}, {}, {'forms': <QuerySet [<DynamicForms: Form 1>]>}]
(0.000) SELECT "institutions_institution"."id", "institutions_institution"."name", "institutions_institution"."abbreviation", "institutions_institution"."city_id", "institutions_institution"."met", "institutions_institution"."moc", "institutions_institution"."ethics", "institutions_institution"."status_request", "institutions_institution"."is_private", "institutions_institution"."ri_1_tools", "institutions_institution"."general", "institutions_institution"."role", "institutions_institution"."type_of_inst", "institutions_institution"."student_count", "institutions_institution"."staff_count", "institutions_institution"."internet_access", "institutions_institution"."online", "institutions_institution"."guest_lectures", "institutions_institution"."environment", "institutions_institution"."focus_pst", "institutions_institution"."further", "institutions_institution"."school_size", "institutions_institution"."community_size", "institutions_institution"."girl_ratio", "institutions_institution"."qualifications", "institutions_institution"."percent_indigenous", "institutions_institution"."age" FROM "institutions_institution" WHERE "institutions_institution"."id" = 1; args=(1,)
(0.000) SELECT "dynamicforms_dynamicforms"."id", "dynamicforms_dynamicforms"."creator_id", "dynamicforms_dynamicforms"."title", "dynamicforms_dynamicforms"."is_active", "dynamicforms_dynamicforms"."creation_time", "dynamicforms_dynamicforms"."expiry_date" FROM "dynamicforms_dynamicforms"; args=()
[mHTTP GET /forms/?download=1 200 [0.01, 127.0.0.1:56636][0m
(0.000) SELECT "django_session"."session_key", "django_session"."session_data", "django_session"."expire_date" FROM "django_session" WHERE ("django_session"."expire_date" > '2019-04-24 15:16:28.075299' AND "django_session"."session_key" = 'bxpt7g6j9sufe1f4vdvfcmhqcijixtqx'); args=('2019-04-24 15:16:28.075299', 'bxpt7g6j9sufe1f4vdvfcmhqcijixtqx')
(0.000) SELECT "users_user"."id", "users_user"."password", "users_user"."last_login", "users_user"."is_superuser", "users_user"."username", "users_user"."first_name", "users_user"."last_name", "users_user"."email", "users_user"."is_staff", "users_user"."is_active", "users_user"."date_joined", "users_user"."phone_number", "users_user"."role", "users_user"."institution_id" FROM "users_user" WHERE "users_user"."id" = 1; args=(1,)
(0.000) SELECT "dynamicforms_dynamicforms"."id", "dynamicforms_dynamicforms"."creator_id", "dynamicforms_dynamicforms"."title", "dynamicforms_dynamicforms"."is_active", "dynamicforms_dynamicforms"."creation_time", "dynamicforms_dynamicforms"."expiry_date" FROM "dynamicforms_dynamicforms" WHERE "dynamicforms_dynamicforms"."id" = 1; args=(1,)
(0.000) SELECT "dynamicforms_questions"."id", "dynamicforms_questions"."form_id_id", "dynamicforms_questions"."question_num", "dynamicforms_questions"."question_text", "dynamicforms_questions"."answer_type", "dynamicforms_questions"."is_active", "dynamicforms_questions"."last_modification_time" FROM "dynamicforms_questions" WHERE "dynamicforms_questions"."form_id_id" = 1; args=(1,)
(0.000) SELECT "dynamicforms_dynamicforms"."id", "dynamicforms_dynamicforms"."creator_id", "dynamicforms_dynamicforms"."title", "dynamicforms_dynamicforms"."is_active", "dynamicforms_dynamicforms"."creation_time", "dynamicforms_dynamicforms"."expiry_date" FROM "dynamicforms_dynamicforms" WHERE "dynamicforms_dynamicforms"."id" = 1; args=(1,)
(0.000) SELECT "dynamicforms_dynamicforms"."id", "dynamicforms_dynamicforms"."creator_id", "dynamicforms_dynamicforms"."title", "dynamicforms_dynamicforms"."is_active", "dynamicforms_dynamicforms"."creation_time", "dynamicforms_dynamicforms"."expiry_date" FROM "dynamicforms_dynamicforms" WHERE "dynamicforms_dynamicforms"."title" = 'Form 1'; args=('Form 1',)
Exception while resolving variable 'title' in template 'dynamicforms/form-edit.html'.
Traceback (most recent call last):
  File "/usr/lib/python3.7/site-packages/django/template/base.py", line 829, in _resolve_lookup
    current = current[bit]
  File "/usr/lib/python3.7/site-packages/django/template/context.py", line 83, in __getitem__
    raise KeyError(key)
KeyError: 'title'

During handling of the above exception, another exception occurred:

Traceback (most recent call last):
  File "/usr/lib/python3.7/site-packages/django/template/base.py", line 835, in _resolve_lookup
    if isinstance(current, BaseContext) and getattr(type(current), bit):
AttributeError: type object 'RequestContext' has no attribute 'title'

During handling of the above exception, another exception occurred:

Traceback (most recent call last):
  File "/usr/lib/python3.7/site-packages/django/template/base.py", line 843, in _resolve_lookup
    current = current[int(bit)]
ValueError: invalid literal for int() with base 10: 'title'

During handling of the above exception, another exception occurred:

Traceback (most recent call last):
  File "/usr/lib/python3.7/site-packages/django/template/base.py", line 850, in _resolve_lookup
    (bit, current))  # missing attribute
django.template.base.VariableDoesNotExist: Failed lookup for key [title] in [{'True': True, 'False': False, 'None': None}, {'csrf_token': <SimpleLazyObject: <function csrf.<locals>._get_val at 0x7ff4f6ab0048>>, 'request': <AsgiRequest: GET '/forms/form-edit/1'>, 'user': <SimpleLazyObject: <User: admin>>, 'perms': <django.contrib.auth.context_processors.PermWrapper object at 0x7ff4f6bfe978>, 'messages': <django.contrib.messages.storage.fallback.FallbackStorage object at 0x7ff4f6b270b8>, 'DEFAULT_MESSAGE_LEVELS': {'DEBUG': 10, 'INFO': 20, 'SUCCESS': 25, 'WARNING': 30, 'ERROR': 40}}, {}, {'form': <DynamicQuestionForm bound=False, valid=Unknown, fields=(title;Question 1;Question 2)>, 'form_title': 'Editing Form Form 1', 'form_pk': 1}]
(0.000) SELECT "institutions_institution"."id", "institutions_institution"."name", "institutions_institution"."abbreviation", "institutions_institution"."city_id", "institutions_institution"."met", "institutions_institution"."moc", "institutions_institution"."ethics", "institutions_institution"."status_request", "institutions_institution"."is_private", "institutions_institution"."ri_1_tools", "institutions_institution"."general", "institutions_institution"."role", "institutions_institution"."type_of_inst", "institutions_institution"."student_count", "institutions_institution"."staff_count", "institutions_institution"."internet_access", "institutions_institution"."online", "institutions_institution"."guest_lectures", "institutions_institution"."environment", "institutions_institution"."focus_pst", "institutions_institution"."further", "institutions_institution"."school_size", "institutions_institution"."community_size", "institutions_institution"."girl_ratio", "institutions_institution"."qualifications", "institutions_institution"."percent_indigenous", "institutions_institution"."age" FROM "institutions_institution" WHERE "institutions_institution"."id" = 1; args=(1,)
Exception while resolving variable 'include_media' in template 'bootstrap4/uni_form.html'.
Traceback (most recent call last):
  File "/usr/lib/python3.7/site-packages/django/template/base.py", line 829, in _resolve_lookup
    current = current[bit]
  File "/usr/lib/python3.7/site-packages/django/template/context.py", line 83, in __getitem__
    raise KeyError(key)
KeyError: 'include_media'

During handling of the above exception, another exception occurred:

Traceback (most recent call last):
  File "/usr/lib/python3.7/site-packages/django/template/base.py", line 835, in _resolve_lookup
    if isinstance(current, BaseContext) and getattr(type(current), bit):
AttributeError: type object 'Context' has no attribute 'include_media'

During handling of the above exception, another exception occurred:

Traceback (most recent call last):
  File "/usr/lib/python3.7/site-packages/django/template/base.py", line 843, in _resolve_lookup
    current = current[int(bit)]
ValueError: invalid literal for int() with base 10: 'include_media'

During handling of the above exception, another exception occurred:

Traceback (most recent call last):
  File "/usr/lib/python3.7/site-packages/django/template/base.py", line 850, in _resolve_lookup
    (bit, current))  # missing attribute
django.template.base.VariableDoesNotExist: Failed lookup for key [include_media] in [{'True': True, 'False': False, 'None': None}, {'True': True, 'False': False, 'None': None, 'form': <DynamicQuestionForm bound=False, valid=Unknown, fields=(title;Question 1;Question 2)>, 'form_show_errors': True, 'form_show_labels': True, 'label_class': '', 'field_class': ''}]
Exception while resolving variable 'tag' in template 'bootstrap4/uni_form.html'.
Traceback (most recent call last):
  File "/usr/lib/python3.7/site-packages/django/template/base.py", line 829, in _resolve_lookup
    current = current[bit]
  File "/usr/lib/python3.7/site-packages/django/template/context.py", line 83, in __getitem__
    raise KeyError(key)
KeyError: 'tag'

During handling of the above exception, another exception occurred:

Traceback (most recent call last):
  File "/usr/lib/python3.7/site-packages/django/template/base.py", line 835, in _resolve_lookup
    if isinstance(current, BaseContext) and getattr(type(current), bit):
AttributeError: type object 'Context' has no attribute 'tag'

During handling of the above exception, another exception occurred:

Traceback (most recent call last):
  File "/usr/lib/python3.7/site-packages/django/template/base.py", line 843, in _resolve_lookup
    current = current[int(bit)]
ValueError: invalid literal for int() with base 10: 'tag'

During handling of the above exception, another exception occurred:

Traceback (most recent call last):
  File "/usr/lib/python3.7/site-packages/django/template/base.py", line 850, in _resolve_lookup
    (bit, current))  # missing attribute
django.template.base.VariableDoesNotExist: Failed lookup for key [tag] in [{'True': True, 'False': False, 'None': None}, {'True': True, 'False': False, 'None': None, 'form': <DynamicQuestionForm bound=False, valid=False, fields=(title;Question 1;Question 2)>, 'form_show_errors': True, 'form_show_labels': True, 'label_class': '', 'field_class': ''}, {'forloop': {'parentloop': {}, 'counter0': 0, 'counter': 1, 'revcounter': 3, 'revcounter0': 2, 'first': True, 'last': False}, 'field': <django.forms.boundfield.BoundField object at 0x7ff4f6abff60>}, {}]
Exception while resolving variable 'form_class' in template 'bootstrap4/uni_form.html'.
Traceback (most recent call last):
  File "/usr/lib/python3.7/site-packages/django/template/base.py", line 829, in _resolve_lookup
    current = current[bit]
  File "/usr/lib/python3.7/site-packages/django/template/context.py", line 83, in __getitem__
    raise KeyError(key)
KeyError: 'form_class'

During handling of the above exception, another exception occurred:

Traceback (most recent call last):
  File "/usr/lib/python3.7/site-packages/django/template/base.py", line 835, in _resolve_lookup
    if isinstance(current, BaseContext) and getattr(type(current), bit):
AttributeError: type object 'Context' has no attribute 'form_class'

During handling of the above exception, another exception occurred:

Traceback (most recent call last):
  File "/usr/lib/python3.7/site-packages/django/template/base.py", line 843, in _resolve_lookup
    current = current[int(bit)]
ValueError: invalid literal for int() with base 10: 'form_class'

During handling of the above exception, another exception occurred:

Traceback (most recent call last):
  File "/usr/lib/python3.7/site-packages/django/template/base.py", line 850, in _resolve_lookup
    (bit, current))  # missing attribute
django.template.base.VariableDoesNotExist: Failed lookup for key [form_class] in [{'True': True, 'False': False, 'None': None}, {'True': True, 'False': False, 'None': None, 'form': <DynamicQuestionForm bound=False, valid=False, fields=(title;Question 1;Question 2)>, 'form_show_errors': True, 'form_show_labels': True, 'label_class': '', 'field_class': ''}, {'forloop': {'parentloop': {}, 'counter0': 0, 'counter': 1, 'revcounter': 3, 'revcounter0': 2, 'first': True, 'last': False}, 'field': <django.forms.boundfield.BoundField object at 0x7ff4f6abff60>}, {}]
Exception while resolving variable 'wrapper_class' in template 'bootstrap4/uni_form.html'.
Traceback (most recent call last):
  File "/usr/lib/python3.7/site-packages/django/template/base.py", line 829, in _resolve_lookup
    current = current[bit]
  File "/usr/lib/python3.7/site-packages/django/template/context.py", line 83, in __getitem__
    raise KeyError(key)
KeyError: 'wrapper_class'

During handling of the above exception, another exception occurred:

Traceback (most recent call last):
  File "/usr/lib/python3.7/site-packages/django/template/base.py", line 835, in _resolve_lookup
    if isinstance(current, BaseContext) and getattr(type(current), bit):
AttributeError: type object 'Context' has no attribute 'wrapper_class'

During handling of the above exception, another exception occurred:

Traceback (most recent call last):
  File "/usr/lib/python3.7/site-packages/django/template/base.py", line 843, in _resolve_lookup
    current = current[int(bit)]
ValueError: invalid literal for int() with base 10: 'wrapper_class'

During handling of the above exception, another exception occurred:

Traceback (most recent call last):
  File "/usr/lib/python3.7/site-packages/django/template/base.py", line 850, in _resolve_lookup
    (bit, current))  # missing attribute
django.template.base.VariableDoesNotExist: Failed lookup for key [wrapper_class] in [{'True': True, 'False': False, 'None': None}, {'True': True, 'False': False, 'None': None, 'form': <DynamicQuestionForm bound=False, valid=False, fields=(title;Question 1;Question 2)>, 'form_show_errors': True, 'form_show_labels': True, 'label_class': '', 'field_class': ''}, {'forloop': {'parentloop': {}, 'counter0': 0, 'counter': 1, 'revcounter': 3, 'revcounter0': 2, 'first': True, 'last': False}, 'field': <django.forms.boundfield.BoundField object at 0x7ff4f6abff60>}, {}]
Exception while resolving variable 'html5_required' in template 'bootstrap4/uni_form.html'.
Traceback (most recent call last):
  File "/usr/lib/python3.7/site-packages/django/template/base.py", line 829, in _resolve_lookup
    current = current[bit]
  File "/usr/lib/python3.7/site-packages/django/template/context.py", line 83, in __getitem__
    raise KeyError(key)
KeyError: 'html5_required'

During handling of the above exception, another exception occurred:

Traceback (most recent call last):
  File "/usr/lib/python3.7/site-packages/django/template/base.py", line 835, in _resolve_lookup
    if isinstance(current, BaseContext) and getattr(type(current), bit):
AttributeError: type object 'Context' has no attribute 'html5_required'

During handling of the above exception, another exception occurred:

Traceback (most recent call last):
  File "/usr/lib/python3.7/site-packages/django/template/base.py", line 843, in _resolve_lookup
    current = current[int(bit)]
ValueError: invalid literal for int() with base 10: 'html5_required'

During handling of the above exception, another exception occurred:

Traceback (most recent call last):
  File "/usr/lib/python3.7/site-packages/django/template/base.py", line 850, in _resolve_lookup
    (bit, current))  # missing attribute
django.template.base.VariableDoesNotExist: Failed lookup for key [html5_required] in [{'True': True, 'False': False, 'None': None}, {'True': True, 'False': False, 'None': None, 'form': <DynamicQuestionForm bound=False, valid=False, fields=(title;Question 1;Question 2)>, 'form_show_errors': True, 'form_show_labels': True, 'label_class': '', 'field_class': ''}, {'forloop': {'parentloop': {}, 'counter0': 0, 'counter': 1, 'revcounter': 3, 'revcounter0': 2, 'first': True, 'last': False}, 'field': <django.forms.boundfield.BoundField object at 0x7ff4f6abff60>}, {}]
Exception while resolving variable 'help_text_inline' in template 'bootstrap4/uni_form.html'.
Traceback (most recent call last):
  File "/usr/lib/python3.7/site-packages/django/template/base.py", line 829, in _resolve_lookup
    current = current[bit]
  File "/usr/lib/python3.7/site-packages/django/template/context.py", line 83, in __getitem__
    raise KeyError(key)
KeyError: 'help_text_inline'

During handling of the above exception, another exception occurred:

Traceback (most recent call last):
  File "/usr/lib/python3.7/site-packages/django/template/base.py", line 835, in _resolve_lookup
    if isinstance(current, BaseContext) and getattr(type(current), bit):
AttributeError: type object 'Context' has no attribute 'help_text_inline'

During handling of the above exception, another exception occurred:

Traceback (most recent call last):
  File "/usr/lib/python3.7/site-packages/django/template/base.py", line 843, in _resolve_lookup
    current = current[int(bit)]
ValueError: invalid literal for int() with base 10: 'help_text_inline'

During handling of the above exception, another exception occurred:

Traceback (most recent call last):
  File "/usr/lib/python3.7/site-packages/django/template/base.py", line 850, in _resolve_lookup
    (bit, current))  # missing attribute
django.template.base.VariableDoesNotExist: Failed lookup for key [help_text_inline] in [{'True': True, 'False': False, 'None': None}, {'True': True, 'False': False, 'None': None, 'form': <DynamicQuestionForm bound=False, valid=False, fields=(title;Question 1;Question 2)>, 'form_show_errors': True, 'form_show_labels': True, 'label_class': '', 'field_class': ''}, {'forloop': {'parentloop': {}, 'counter0': 0, 'counter': 1, 'revcounter': 3, 'revcounter0': 2, 'first': True, 'last': False}, 'field': <django.forms.boundfield.BoundField object at 0x7ff4f6abff60>}, {}, {}]
Exception while resolving variable 'error_text_inline' in template 'bootstrap4/uni_form.html'.
Traceback (most recent call last):
  File "/usr/lib/python3.7/site-packages/django/template/base.py", line 829, in _resolve_lookup
    current = current[bit]
  File "/usr/lib/python3.7/site-packages/django/template/context.py", line 83, in __getitem__
    raise KeyError(key)
KeyError: 'error_text_inline'

During handling of the above exception, another exception occurred:

Traceback (most recent call last):
  File "/usr/lib/python3.7/site-packages/django/template/base.py", line 835, in _resolve_lookup
    if isinstance(current, BaseContext) and getattr(type(current), bit):
AttributeError: type object 'Context' has no attribute 'error_text_inline'

During handling of the above exception, another exception occurred:

Traceback (most recent call last):
  File "/usr/lib/python3.7/site-packages/django/template/base.py", line 843, in _resolve_lookup
    current = current[int(bit)]
ValueError: invalid literal for int() with base 10: 'error_text_inline'

During handling of the above exception, another exception occurred:

Traceback (most recent call last):
  File "/usr/lib/python3.7/site-packages/django/template/base.py", line 850, in _resolve_lookup
    (bit, current))  # missing attribute
django.template.base.VariableDoesNotExist: Failed lookup for key [error_text_inline] in [{'True': True, 'False': False, 'None': None}, {'True': True, 'False': False, 'None': None, 'form': <DynamicQuestionForm bound=False, valid=False, fields=(title;Question 1;Question 2)>, 'form_show_errors': True, 'form_show_labels': True, 'label_class': '', 'field_class': ''}, {'forloop': {'parentloop': {}, 'counter0': 0, 'counter': 1, 'revcounter': 3, 'revcounter0': 2, 'first': True, 'last': False}, 'field': <django.forms.boundfield.BoundField object at 0x7ff4f6abff60>}, {}, {}]
Exception while resolving variable 'help_text_inline' in template 'bootstrap4/uni_form.html'.
Traceback (most recent call last):
  File "/usr/lib/python3.7/site-packages/django/template/base.py", line 829, in _resolve_lookup
    current = current[bit]
  File "/usr/lib/python3.7/site-packages/django/template/context.py", line 83, in __getitem__
    raise KeyError(key)
KeyError: 'help_text_inline'

During handling of the above exception, another exception occurred:

Traceback (most recent call last):
  File "/usr/lib/python3.7/site-packages/django/template/base.py", line 835, in _resolve_lookup
    if isinstance(current, BaseContext) and getattr(type(current), bit):
AttributeError: type object 'Context' has no attribute 'help_text_inline'

During handling of the above exception, another exception occurred:

Traceback (most recent call last):
  File "/usr/lib/python3.7/site-packages/django/template/base.py", line 843, in _resolve_lookup
    current = current[int(bit)]
ValueError: invalid literal for int() with base 10: 'help_text_inline'

During handling of the above exception, another exception occurred:

Traceback (most recent call last):
  File "/usr/lib/python3.7/site-packages/django/template/base.py", line 850, in _resolve_lookup
    (bit, current))  # missing attribute
django.template.base.VariableDoesNotExist: Failed lookup for key [help_text_inline] in [{'True': True, 'False': False, 'None': None}, {'True': True, 'False': False, 'None': None, 'form': <DynamicQuestionForm bound=False, valid=False, fields=(title;Question 1;Question 2)>, 'form_show_errors': True, 'form_show_labels': True, 'label_class': '', 'field_class': ''}, {'forloop': {'parentloop': {}, 'counter0': 0, 'counter': 1, 'revcounter': 3, 'revcounter0': 2, 'first': True, 'last': False}, 'field': <django.forms.boundfield.BoundField object at 0x7ff4f6abff60>}, {}, {}]
Exception while resolving variable 'tag' in template 'bootstrap4/uni_form.html'.
Traceback (most recent call last):
  File "/usr/lib/python3.7/site-packages/django/template/base.py", line 829, in _resolve_lookup
    current = current[bit]
  File "/usr/lib/python3.7/site-packages/django/template/context.py", line 83, in __getitem__
    raise KeyError(key)
KeyError: 'tag'

During handling of the above exception, another exception occurred:

Traceback (most recent call last):
  File "/usr/lib/python3.7/site-packages/django/template/base.py", line 835, in _resolve_lookup
    if isinstance(current, BaseContext) and getattr(type(current), bit):
AttributeError: type object 'Context' has no attribute 'tag'

During handling of the above exception, another exception occurred:

Traceback (most recent call last):
  File "/usr/lib/python3.7/site-packages/django/template/base.py", line 843, in _resolve_lookup
    current = current[int(bit)]
ValueError: invalid literal for int() with base 10: 'tag'

During handling of the above exception, another exception occurred:

Traceback (most recent call last):
  File "/usr/lib/python3.7/site-packages/django/template/base.py", line 850, in _resolve_lookup
    (bit, current))  # missing attribute
django.template.base.VariableDoesNotExist: Failed lookup for key [tag] in [{'True': True, 'False': False, 'None': None}, {'True': True, 'False': False, 'None': None, 'form': <DynamicQuestionForm bound=False, valid=False, fields=(title;Question 1;Question 2)>, 'form_show_errors': True, 'form_show_labels': True, 'label_class': '', 'field_class': ''}, {'forloop': {'parentloop': {}, 'counter0': 0, 'counter': 1, 'revcounter': 3, 'revcounter0': 2, 'first': True, 'last': False}, 'field': <django.forms.boundfield.BoundField object at 0x7ff4f6abff60>}, {}]
Exception while resolving variable 'tag' in template 'bootstrap4/uni_form.html'.
Traceback (most recent call last):
  File "/usr/lib/python3.7/site-packages/django/template/base.py", line 829, in _resolve_lookup
    current = current[bit]
  File "/usr/lib/python3.7/site-packages/django/template/context.py", line 83, in __getitem__
    raise KeyError(key)
KeyError: 'tag'

During handling of the above exception, another exception occurred:

Traceback (most recent call last):
  File "/usr/lib/python3.7/site-packages/django/template/base.py", line 835, in _resolve_lookup
    if isinstance(current, BaseContext) and getattr(type(current), bit):
AttributeError: type object 'Context' has no attribute 'tag'

During handling of the above exception, another exception occurred:

Traceback (most recent call last):
  File "/usr/lib/python3.7/site-packages/django/template/base.py", line 843, in _resolve_lookup
    current = current[int(bit)]
ValueError: invalid literal for int() with base 10: 'tag'

During handling of the above exception, another exception occurred:

Traceback (most recent call last):
  File "/usr/lib/python3.7/site-packages/django/template/base.py", line 850, in _resolve_lookup
    (bit, current))  # missing attribute
django.template.base.VariableDoesNotExist: Failed lookup for key [tag] in [{'True': True, 'False': False, 'None': None}, {'True': True, 'False': False, 'None': None, 'form': <DynamicQuestionForm bound=False, valid=False, fields=(title;Question 1;Question 2)>, 'form_show_errors': True, 'form_show_labels': True, 'label_class': '', 'field_class': ''}, {'forloop': {'parentloop': {}, 'counter0': 1, 'counter': 2, 'revcounter': 2, 'revcounter0': 1, 'first': False, 'last': False}, 'field': <django.forms.boundfield.BoundField object at 0x7ff4f6abfef0>}, {}]
Exception while resolving variable 'form_class' in template 'bootstrap4/uni_form.html'.
Traceback (most recent call last):
  File "/usr/lib/python3.7/site-packages/django/template/base.py", line 829, in _resolve_lookup
    current = current[bit]
  File "/usr/lib/python3.7/site-packages/django/template/context.py", line 83, in __getitem__
    raise KeyError(key)
KeyError: 'form_class'

During handling of the above exception, another exception occurred:

Traceback (most recent call last):
  File "/usr/lib/python3.7/site-packages/django/template/base.py", line 835, in _resolve_lookup
    if isinstance(current, BaseContext) and getattr(type(current), bit):
AttributeError: type object 'Context' has no attribute 'form_class'

During handling of the above exception, another exception occurred:

Traceback (most recent call last):
  File "/usr/lib/python3.7/site-packages/django/template/base.py", line 843, in _resolve_lookup
    current = current[int(bit)]
ValueError: invalid literal for int() with base 10: 'form_class'

During handling of the above exception, another exception occurred:

Traceback (most recent call last):
  File "/usr/lib/python3.7/site-packages/django/template/base.py", line 850, in _resolve_lookup
    (bit, current))  # missing attribute
django.template.base.VariableDoesNotExist: Failed lookup for key [form_class] in [{'True': True, 'False': False, 'None': None}, {'True': True, 'False': False, 'None': None, 'form': <DynamicQuestionForm bound=False, valid=False, fields=(title;Question 1;Question 2)>, 'form_show_errors': True, 'form_show_labels': True, 'label_class': '', 'field_class': ''}, {'forloop': {'parentloop': {}, 'counter0': 1, 'counter': 2, 'revcounter': 2, 'revcounter0': 1, 'first': False, 'last': False}, 'field': <django.forms.boundfield.BoundField object at 0x7ff4f6abfef0>}, {}]
Exception while resolving variable 'wrapper_class' in template 'bootstrap4/uni_form.html'.
Traceback (most recent call last):
  File "/usr/lib/python3.7/site-packages/django/template/base.py", line 829, in _resolve_lookup
    current = current[bit]
  File "/usr/lib/python3.7/site-packages/django/template/context.py", line 83, in __getitem__
    raise KeyError(key)
KeyError: 'wrapper_class'

During handling of the above exception, another exception occurred:

Traceback (most recent call last):
  File "/usr/lib/python3.7/site-packages/django/template/base.py", line 835, in _resolve_lookup
    if isinstance(current, BaseContext) and getattr(type(current), bit):
AttributeError: type object 'Context' has no attribute 'wrapper_class'

During handling of the above exception, another exception occurred:

Traceback (most recent call last):
  File "/usr/lib/python3.7/site-packages/django/template/base.py", line 843, in _resolve_lookup
    current = current[int(bit)]
ValueError: invalid literal for int() with base 10: 'wrapper_class'

During handling of the above exception, another exception occurred:

Traceback (most recent call last):
  File "/usr/lib/python3.7/site-packages/django/template/base.py", line 850, in _resolve_lookup
    (bit, current))  # missing attribute
django.template.base.VariableDoesNotExist: Failed lookup for key [wrapper_class] in [{'True': True, 'False': False, 'None': None}, {'True': True, 'False': False, 'None': None, 'form': <DynamicQuestionForm bound=False, valid=False, fields=(title;Question 1;Question 2)>, 'form_show_errors': True, 'form_show_labels': True, 'label_class': '', 'field_class': ''}, {'forloop': {'parentloop': {}, 'counter0': 1, 'counter': 2, 'revcounter': 2, 'revcounter0': 1, 'first': False, 'last': False}, 'field': <django.forms.boundfield.BoundField object at 0x7ff4f6abfef0>}, {}]
Exception while resolving variable 'html5_required' in template 'bootstrap4/uni_form.html'.
Traceback (most recent call last):
  File "/usr/lib/python3.7/site-packages/django/template/base.py", line 829, in _resolve_lookup
    current = current[bit]
  File "/usr/lib/python3.7/site-packages/django/template/context.py", line 83, in __getitem__
    raise KeyError(key)
KeyError: 'html5_required'

During handling of the above exception, another exception occurred:

Traceback (most recent call last):
  File "/usr/lib/python3.7/site-packages/django/template/base.py", line 835, in _resolve_lookup
    if isinstance(current, BaseContext) and getattr(type(current), bit):
AttributeError: type object 'Context' has no attribute 'html5_required'

During handling of the above exception, another exception occurred:

Traceback (most recent call last):
  File "/usr/lib/python3.7/site-packages/django/template/base.py", line 843, in _resolve_lookup
    current = current[int(bit)]
ValueError: invalid literal for int() with base 10: 'html5_required'

During handling of the above exception, another exception occurred:

Traceback (most recent call last):
  File "/usr/lib/python3.7/site-packages/django/template/base.py", line 850, in _resolve_lookup
    (bit, current))  # missing attribute
django.template.base.VariableDoesNotExist: Failed lookup for key [html5_required] in [{'True': True, 'False': False, 'None': None}, {'True': True, 'False': False, 'None': None, 'form': <DynamicQuestionForm bound=False, valid=False, fields=(title;Question 1;Question 2)>, 'form_show_errors': True, 'form_show_labels': True, 'label_class': '', 'field_class': ''}, {'forloop': {'parentloop': {}, 'counter0': 1, 'counter': 2, 'revcounter': 2, 'revcounter0': 1, 'first': False, 'last': False}, 'field': <django.forms.boundfield.BoundField object at 0x7ff4f6abfef0>}, {}]
Exception while resolving variable 'help_text_inline' in template 'bootstrap4/uni_form.html'.
Traceback (most recent call last):
  File "/usr/lib/python3.7/site-packages/django/template/base.py", line 829, in _resolve_lookup
    current = current[bit]
  File "/usr/lib/python3.7/site-packages/django/template/context.py", line 83, in __getitem__
    raise KeyError(key)
KeyError: 'help_text_inline'

During handling of the above exception, another exception occurred:

Traceback (most recent call last):
  File "/usr/lib/python3.7/site-packages/django/template/base.py", line 835, in _resolve_lookup
    if isinstance(current, BaseContext) and getattr(type(current), bit):
AttributeError: type object 'Context' has no attribute 'help_text_inline'

During handling of the above exception, another exception occurred:

Traceback (most recent call last):
  File "/usr/lib/python3.7/site-packages/django/template/base.py", line 843, in _resolve_lookup
    current = current[int(bit)]
ValueError: invalid literal for int() with base 10: 'help_text_inline'

During handling of the above exception, another exception occurred:

Traceback (most recent call last):
  File "/usr/lib/python3.7/site-packages/django/template/base.py", line 850, in _resolve_lookup
    (bit, current))  # missing attribute
django.template.base.VariableDoesNotExist: Failed lookup for key [help_text_inline] in [{'True': True, 'False': False, 'None': None}, {'True': True, 'False': False, 'None': None, 'form': <DynamicQuestionForm bound=False, valid=False, fields=(title;Question 1;Question 2)>, 'form_show_errors': True, 'form_show_labels': True, 'label_class': '', 'field_class': ''}, {'forloop': {'parentloop': {}, 'counter0': 1, 'counter': 2, 'revcounter': 2, 'revcounter0': 1, 'first': False, 'last': False}, 'field': <django.forms.boundfield.BoundField object at 0x7ff4f6abfef0>}, {}, {}]
Exception while resolving variable 'error_text_inline' in template 'bootstrap4/uni_form.html'.
Traceback (most recent call last):
  File "/usr/lib/python3.7/site-packages/django/template/base.py", line 829, in _resolve_lookup
    current = current[bit]
  File "/usr/lib/python3.7/site-packages/django/template/context.py", line 83, in __getitem__
    raise KeyError(key)
KeyError: 'error_text_inline'

During handling of the above exception, another exception occurred:

Traceback (most recent call last):
  File "/usr/lib/python3.7/site-packages/django/template/base.py", line 835, in _resolve_lookup
    if isinstance(current, BaseContext) and getattr(type(current), bit):
AttributeError: type object 'Context' has no attribute 'error_text_inline'

During handling of the above exception, another exception occurred:

Traceback (most recent call last):
  File "/usr/lib/python3.7/site-packages/django/template/base.py", line 843, in _resolve_lookup
    current = current[int(bit)]
ValueError: invalid literal for int() with base 10: 'error_text_inline'

During handling of the above exception, another exception occurred:

Traceback (most recent call last):
  File "/usr/lib/python3.7/site-packages/django/template/base.py", line 850, in _resolve_lookup
    (bit, current))  # missing attribute
django.template.base.VariableDoesNotExist: Failed lookup for key [error_text_inline] in [{'True': True, 'False': False, 'None': None}, {'True': True, 'False': False, 'None': None, 'form': <DynamicQuestionForm bound=False, valid=False, fields=(title;Question 1;Question 2)>, 'form_show_errors': True, 'form_show_labels': True, 'label_class': '', 'field_class': ''}, {'forloop': {'parentloop': {}, 'counter0': 1, 'counter': 2, 'revcounter': 2, 'revcounter0': 1, 'first': False, 'last': False}, 'field': <django.forms.boundfield.BoundField object at 0x7ff4f6abfef0>}, {}, {}]
Exception while resolving variable 'help_text_inline' in template 'bootstrap4/uni_form.html'.
Traceback (most recent call last):
  File "/usr/lib/python3.7/site-packages/django/template/base.py", line 829, in _resolve_lookup
    current = current[bit]
  File "/usr/lib/python3.7/site-packages/django/template/context.py", line 83, in __getitem__
    raise KeyError(key)
KeyError: 'help_text_inline'

During handling of the above exception, another exception occurred:

Traceback (most recent call last):
  File "/usr/lib/python3.7/site-packages/django/template/base.py", line 835, in _resolve_lookup
    if isinstance(current, BaseContext) and getattr(type(current), bit):
AttributeError: type object 'Context' has no attribute 'help_text_inline'

During handling of the above exception, another exception occurred:

Traceback (most recent call last):
  File "/usr/lib/python3.7/site-packages/django/template/base.py", line 843, in _resolve_lookup
    current = current[int(bit)]
ValueError: invalid literal for int() with base 10: 'help_text_inline'

During handling of the above exception, another exception occurred:

Traceback (most recent call last):
  File "/usr/lib/python3.7/site-packages/django/template/base.py", line 850, in _resolve_lookup
    (bit, current))  # missing attribute
django.template.base.VariableDoesNotExist: Failed lookup for key [help_text_inline] in [{'True': True, 'False': False, 'None': None}, {'True': True, 'False': False, 'None': None, 'form': <DynamicQuestionForm bound=False, valid=False, fields=(title;Question 1;Question 2)>, 'form_show_errors': True, 'form_show_labels': True, 'label_class': '', 'field_class': ''}, {'forloop': {'parentloop': {}, 'counter0': 1, 'counter': 2, 'revcounter': 2, 'revcounter0': 1, 'first': False, 'last': False}, 'field': <django.forms.boundfield.BoundField object at 0x7ff4f6abfef0>}, {}, {}]
Exception while resolving variable 'tag' in template 'bootstrap4/uni_form.html'.
Traceback (most recent call last):
  File "/usr/lib/python3.7/site-packages/django/template/base.py", line 829, in _resolve_lookup
    current = current[bit]
  File "/usr/lib/python3.7/site-packages/django/template/context.py", line 83, in __getitem__
    raise KeyError(key)
KeyError: 'tag'

During handling of the above exception, another exception occurred:

Traceback (most recent call last):
  File "/usr/lib/python3.7/site-packages/django/template/base.py", line 835, in _resolve_lookup
    if isinstance(current, BaseContext) and getattr(type(current), bit):
AttributeError: type object 'Context' has no attribute 'tag'

During handling of the above exception, another exception occurred:

Traceback (most recent call last):
  File "/usr/lib/python3.7/site-packages/django/template/base.py", line 843, in _resolve_lookup
    current = current[int(bit)]
ValueError: invalid literal for int() with base 10: 'tag'

During handling of the above exception, another exception occurred:

Traceback (most recent call last):
  File "/usr/lib/python3.7/site-packages/django/template/base.py", line 850, in _resolve_lookup
    (bit, current))  # missing attribute
django.template.base.VariableDoesNotExist: Failed lookup for key [tag] in [{'True': True, 'False': False, 'None': None}, {'True': True, 'False': False, 'None': None, 'form': <DynamicQuestionForm bound=False, valid=False, fields=(title;Question 1;Question 2)>, 'form_show_errors': True, 'form_show_labels': True, 'label_class': '', 'field_class': ''}, {'forloop': {'parentloop': {}, 'counter0': 1, 'counter': 2, 'revcounter': 2, 'revcounter0': 1, 'first': False, 'last': False}, 'field': <django.forms.boundfield.BoundField object at 0x7ff4f6abfef0>}, {}]
Exception while resolving variable 'tag' in template 'bootstrap4/uni_form.html'.
Traceback (most recent call last):
  File "/usr/lib/python3.7/site-packages/django/template/base.py", line 829, in _resolve_lookup
    current = current[bit]
  File "/usr/lib/python3.7/site-packages/django/template/context.py", line 83, in __getitem__
    raise KeyError(key)
KeyError: 'tag'

During handling of the above exception, another exception occurred:

Traceback (most recent call last):
  File "/usr/lib/python3.7/site-packages/django/template/base.py", line 835, in _resolve_lookup
    if isinstance(current, BaseContext) and getattr(type(current), bit):
AttributeError: type object 'Context' has no attribute 'tag'

During handling of the above exception, another exception occurred:

Traceback (most recent call last):
  File "/usr/lib/python3.7/site-packages/django/template/base.py", line 843, in _resolve_lookup
    current = current[int(bit)]
ValueError: invalid literal for int() with base 10: 'tag'

During handling of the above exception, another exception occurred:

Traceback (most recent call last):
  File "/usr/lib/python3.7/site-packages/django/template/base.py", line 850, in _resolve_lookup
    (bit, current))  # missing attribute
django.template.base.VariableDoesNotExist: Failed lookup for key [tag] in [{'True': True, 'False': False, 'None': None}, {'True': True, 'False': False, 'None': None, 'form': <DynamicQuestionForm bound=False, valid=False, fields=(title;Question 1;Question 2)>, 'form_show_errors': True, 'form_show_labels': True, 'label_class': '', 'field_class': ''}, {'forloop': {'parentloop': {}, 'counter0': 2, 'counter': 3, 'revcounter': 1, 'revcounter0': 0, 'first': False, 'last': True}, 'field': <django.forms.boundfield.BoundField object at 0x7ff4f4254710>}, {}]
Exception while resolving variable 'form_class' in template 'bootstrap4/uni_form.html'.
Traceback (most recent call last):
  File "/usr/lib/python3.7/site-packages/django/template/base.py", line 829, in _resolve_lookup
    current = current[bit]
  File "/usr/lib/python3.7/site-packages/django/template/context.py", line 83, in __getitem__
    raise KeyError(key)
KeyError: 'form_class'

During handling of the above exception, another exception occurred:

Traceback (most recent call last):
  File "/usr/lib/python3.7/site-packages/django/template/base.py", line 835, in _resolve_lookup
    if isinstance(current, BaseContext) and getattr(type(current), bit):
AttributeError: type object 'Context' has no attribute 'form_class'

During handling of the above exception, another exception occurred:

Traceback (most recent call last):
  File "/usr/lib/python3.7/site-packages/django/template/base.py", line 843, in _resolve_lookup
    current = current[int(bit)]
ValueError: invalid literal for int() with base 10: 'form_class'

During handling of the above exception, another exception occurred:

Traceback (most recent call last):
  File "/usr/lib/python3.7/site-packages/django/template/base.py", line 850, in _resolve_lookup
    (bit, current))  # missing attribute
django.template.base.VariableDoesNotExist: Failed lookup for key [form_class] in [{'True': True, 'False': False, 'None': None}, {'True': True, 'False': False, 'None': None, 'form': <DynamicQuestionForm bound=False, valid=False, fields=(title;Question 1;Question 2)>, 'form_show_errors': True, 'form_show_labels': True, 'label_class': '', 'field_class': ''}, {'forloop': {'parentloop': {}, 'counter0': 2, 'counter': 3, 'revcounter': 1, 'revcounter0': 0, 'first': False, 'last': True}, 'field': <django.forms.boundfield.BoundField object at 0x7ff4f4254710>}, {}]
Exception while resolving variable 'wrapper_class' in template 'bootstrap4/uni_form.html'.
Traceback (most recent call last):
  File "/usr/lib/python3.7/site-packages/django/template/base.py", line 829, in _resolve_lookup
    current = current[bit]
  File "/usr/lib/python3.7/site-packages/django/template/context.py", line 83, in __getitem__
    raise KeyError(key)
KeyError: 'wrapper_class'

During handling of the above exception, another exception occurred:

Traceback (most recent call last):
  File "/usr/lib/python3.7/site-packages/django/template/base.py", line 835, in _resolve_lookup
    if isinstance(current, BaseContext) and getattr(type(current), bit):
AttributeError: type object 'Context' has no attribute 'wrapper_class'

During handling of the above exception, another exception occurred:

Traceback (most recent call last):
  File "/usr/lib/python3.7/site-packages/django/template/base.py", line 843, in _resolve_lookup
    current = current[int(bit)]
ValueError: invalid literal for int() with base 10: 'wrapper_class'

During handling of the above exception, another exception occurred:

Traceback (most recent call last):
  File "/usr/lib/python3.7/site-packages/django/template/base.py", line 850, in _resolve_lookup
    (bit, current))  # missing attribute
django.template.base.VariableDoesNotExist: Failed lookup for key [wrapper_class] in [{'True': True, 'False': False, 'None': None}, {'True': True, 'False': False, 'None': None, 'form': <DynamicQuestionForm bound=False, valid=False, fields=(title;Question 1;Question 2)>, 'form_show_errors': True, 'form_show_labels': True, 'label_class': '', 'field_class': ''}, {'forloop': {'parentloop': {}, 'counter0': 2, 'counter': 3, 'revcounter': 1, 'revcounter0': 0, 'first': False, 'last': True}, 'field': <django.forms.boundfield.BoundField object at 0x7ff4f4254710>}, {}]
Exception while resolving variable 'html5_required' in template 'bootstrap4/uni_form.html'.
Traceback (most recent call last):
  File "/usr/lib/python3.7/site-packages/django/template/base.py", line 829, in _resolve_lookup
    current = current[bit]
  File "/usr/lib/python3.7/site-packages/django/template/context.py", line 83, in __getitem__
    raise KeyError(key)
KeyError: 'html5_required'

During handling of the above exception, another exception occurred:

Traceback (most recent call last):
  File "/usr/lib/python3.7/site-packages/django/template/base.py", line 835, in _resolve_lookup
    if isinstance(current, BaseContext) and getattr(type(current), bit):
AttributeError: type object 'Context' has no attribute 'html5_required'

During handling of the above exception, another exception occurred:

Traceback (most recent call last):
  File "/usr/lib/python3.7/site-packages/django/template/base.py", line 843, in _resolve_lookup
    current = current[int(bit)]
ValueError: invalid literal for int() with base 10: 'html5_required'

During handling of the above exception, another exception occurred:

Traceback (most recent call last):
  File "/usr/lib/python3.7/site-packages/django/template/base.py", line 850, in _resolve_lookup
    (bit, current))  # missing attribute
django.template.base.VariableDoesNotExist: Failed lookup for key [html5_required] in [{'True': True, 'False': False, 'None': None}, {'True': True, 'False': False, 'None': None, 'form': <DynamicQuestionForm bound=False, valid=False, fields=(title;Question 1;Question 2)>, 'form_show_errors': True, 'form_show_labels': True, 'label_class': '', 'field_class': ''}, {'forloop': {'parentloop': {}, 'counter0': 2, 'counter': 3, 'revcounter': 1, 'revcounter0': 0, 'first': False, 'last': True}, 'field': <django.forms.boundfield.BoundField object at 0x7ff4f4254710>}, {}]
Exception while resolving variable 'help_text_inline' in template 'bootstrap4/uni_form.html'.
Traceback (most recent call last):
  File "/usr/lib/python3.7/site-packages/django/template/base.py", line 829, in _resolve_lookup
    current = current[bit]
  File "/usr/lib/python3.7/site-packages/django/template/context.py", line 83, in __getitem__
    raise KeyError(key)
KeyError: 'help_text_inline'

During handling of the above exception, another exception occurred:

Traceback (most recent call last):
  File "/usr/lib/python3.7/site-packages/django/template/base.py", line 835, in _resolve_lookup
    if isinstance(current, BaseContext) and getattr(type(current), bit):
AttributeError: type object 'Context' has no attribute 'help_text_inline'

During handling of the above exception, another exception occurred:

Traceback (most recent call last):
  File "/usr/lib/python3.7/site-packages/django/template/base.py", line 843, in _resolve_lookup
    current = current[int(bit)]
ValueError: invalid literal for int() with base 10: 'help_text_inline'

During handling of the above exception, another exception occurred:

Traceback (most recent call last):
  File "/usr/lib/python3.7/site-packages/django/template/base.py", line 850, in _resolve_lookup
    (bit, current))  # missing attribute
django.template.base.VariableDoesNotExist: Failed lookup for key [help_text_inline] in [{'True': True, 'False': False, 'None': None}, {'True': True, 'False': False, 'None': None, 'form': <DynamicQuestionForm bound=False, valid=False, fields=(title;Question 1;Question 2)>, 'form_show_errors': True, 'form_show_labels': True, 'label_class': '', 'field_class': ''}, {'forloop': {'parentloop': {}, 'counter0': 2, 'counter': 3, 'revcounter': 1, 'revcounter0': 0, 'first': False, 'last': True}, 'field': <django.forms.boundfield.BoundField object at 0x7ff4f4254710>}, {}, {}]
Exception while resolving variable 'error_text_inline' in template 'bootstrap4/uni_form.html'.
Traceback (most recent call last):
  File "/usr/lib/python3.7/site-packages/django/template/base.py", line 829, in _resolve_lookup
    current = current[bit]
  File "/usr/lib/python3.7/site-packages/django/template/context.py", line 83, in __getitem__
    raise KeyError(key)
KeyError: 'error_text_inline'

During handling of the above exception, another exception occurred:

Traceback (most recent call last):
  File "/usr/lib/python3.7/site-packages/django/template/base.py", line 835, in _resolve_lookup
    if isinstance(current, BaseContext) and getattr(type(current), bit):
AttributeError: type object 'Context' has no attribute 'error_text_inline'

During handling of the above exception, another exception occurred:

Traceback (most recent call last):
  File "/usr/lib/python3.7/site-packages/django/template/base.py", line 843, in _resolve_lookup
    current = current[int(bit)]
ValueError: invalid literal for int() with base 10: 'error_text_inline'

During handling of the above exception, another exception occurred:

Traceback (most recent call last):
  File "/usr/lib/python3.7/site-packages/django/template/base.py", line 850, in _resolve_lookup
    (bit, current))  # missing attribute
django.template.base.VariableDoesNotExist: Failed lookup for key [error_text_inline] in [{'True': True, 'False': False, 'None': None}, {'True': True, 'False': False, 'None': None, 'form': <DynamicQuestionForm bound=False, valid=False, fields=(title;Question 1;Question 2)>, 'form_show_errors': True, 'form_show_labels': True, 'label_class': '', 'field_class': ''}, {'forloop': {'parentloop': {}, 'counter0': 2, 'counter': 3, 'revcounter': 1, 'revcounter0': 0, 'first': False, 'last': True}, 'field': <django.forms.boundfield.BoundField object at 0x7ff4f4254710>}, {}, {}]
Exception while resolving variable 'help_text_inline' in template 'bootstrap4/uni_form.html'.
Traceback (most recent call last):
  File "/usr/lib/python3.7/site-packages/django/template/base.py", line 829, in _resolve_lookup
    current = current[bit]
  File "/usr/lib/python3.7/site-packages/django/template/context.py", line 83, in __getitem__
    raise KeyError(key)
KeyError: 'help_text_inline'

During handling of the above exception, another exception occurred:

Traceback (most recent call last):
  File "/usr/lib/python3.7/site-packages/django/template/base.py", line 835, in _resolve_lookup
    if isinstance(current, BaseContext) and getattr(type(current), bit):
AttributeError: type object 'Context' has no attribute 'help_text_inline'

During handling of the above exception, another exception occurred:

Traceback (most recent call last):
  File "/usr/lib/python3.7/site-packages/django/template/base.py", line 843, in _resolve_lookup
    current = current[int(bit)]
ValueError: invalid literal for int() with base 10: 'help_text_inline'

During handling of the above exception, another exception occurred:

Traceback (most recent call last):
  File "/usr/lib/python3.7/site-packages/django/template/base.py", line 850, in _resolve_lookup
    (bit, current))  # missing attribute
django.template.base.VariableDoesNotExist: Failed lookup for key [help_text_inline] in [{'True': True, 'False': False, 'None': None}, {'True': True, 'False': False, 'None': None, 'form': <DynamicQuestionForm bound=False, valid=False, fields=(title;Question 1;Question 2)>, 'form_show_errors': True, 'form_show_labels': True, 'label_class': '', 'field_class': ''}, {'forloop': {'parentloop': {}, 'counter0': 2, 'counter': 3, 'revcounter': 1, 'revcounter0': 0, 'first': False, 'last': True}, 'field': <django.forms.boundfield.BoundField object at 0x7ff4f4254710>}, {}, {}]
Exception while resolving variable 'tag' in template 'bootstrap4/uni_form.html'.
Traceback (most recent call last):
  File "/usr/lib/python3.7/site-packages/django/template/base.py", line 829, in _resolve_lookup
    current = current[bit]
  File "/usr/lib/python3.7/site-packages/django/template/context.py", line 83, in __getitem__
    raise KeyError(key)
KeyError: 'tag'

During handling of the above exception, another exception occurred:

Traceback (most recent call last):
  File "/usr/lib/python3.7/site-packages/django/template/base.py", line 835, in _resolve_lookup
    if isinstance(current, BaseContext) and getattr(type(current), bit):
AttributeError: type object 'Context' has no attribute 'tag'

During handling of the above exception, another exception occurred:

Traceback (most recent call last):
  File "/usr/lib/python3.7/site-packages/django/template/base.py", line 843, in _resolve_lookup
    current = current[int(bit)]
ValueError: invalid literal for int() with base 10: 'tag'

During handling of the above exception, another exception occurred:

Traceback (most recent call last):
  File "/usr/lib/python3.7/site-packages/django/template/base.py", line 850, in _resolve_lookup
    (bit, current))  # missing attribute
django.template.base.VariableDoesNotExist: Failed lookup for key [tag] in [{'True': True, 'False': False, 'None': None}, {'True': True, 'False': False, 'None': None, 'form': <DynamicQuestionForm bound=False, valid=False, fields=(title;Question 1;Question 2)>, 'form_show_errors': True, 'form_show_labels': True, 'label_class': '', 'field_class': ''}, {'forloop': {'parentloop': {}, 'counter0': 2, 'counter': 3, 'revcounter': 1, 'revcounter0': 0, 'first': False, 'last': True}, 'field': <django.forms.boundfield.BoundField object at 0x7ff4f4254710>}, {}]
[mHTTP GET /forms/form-edit/1 200 [0.03, 127.0.0.1:56636][0m
(0.000) SELECT COUNT(*) AS "__count" FROM "blog_post"; args=()
(0.000) SELECT "blog_post"."id", "blog_post"."title", "blog_post"."content", "blog_post"."date_posted", "blog_post"."date_expired", "blog_post"."author_id", "blog_post"."fileAttachment", "blog_post"."imageAttachment" FROM "blog_post" ORDER BY "blog_post"."date_posted" DESC  LIMIT 1; args=()
(0.000) SELECT "blog_post"."id", "blog_post"."title", "blog_post"."content", "blog_post"."date_posted", "blog_post"."date_expired", "blog_post"."author_id", "blog_post"."fileAttachment", "blog_post"."imageAttachment" FROM "blog_post" ORDER BY "blog_post"."date_posted" DESC  LIMIT 1; args=()
Exception while resolving variable 'title' in template 'blog/home.html'.
Traceback (most recent call last):
  File "/usr/lib/python3.7/site-packages/django/template/base.py", line 829, in _resolve_lookup
    current = current[bit]
  File "/usr/lib/python3.7/site-packages/django/template/context.py", line 83, in __getitem__
    raise KeyError(key)
KeyError: 'title'

During handling of the above exception, another exception occurred:

Traceback (most recent call last):
  File "/usr/lib/python3.7/site-packages/django/template/base.py", line 835, in _resolve_lookup
    if isinstance(current, BaseContext) and getattr(type(current), bit):
AttributeError: type object 'RequestContext' has no attribute 'title'

During handling of the above exception, another exception occurred:

Traceback (most recent call last):
  File "/usr/lib/python3.7/site-packages/django/template/base.py", line 843, in _resolve_lookup
    current = current[int(bit)]
ValueError: invalid literal for int() with base 10: 'title'

During handling of the above exception, another exception occurred:

Traceback (most recent call last):
  File "/usr/lib/python3.7/site-packages/django/template/base.py", line 850, in _resolve_lookup
    (bit, current))  # missing attribute
django.template.base.VariableDoesNotExist: Failed lookup for key [title] in [{'True': True, 'False': False, 'None': None}, {'csrf_token': <SimpleLazyObject: <function csrf.<locals>._get_val at 0x7ff4f6aa8840>>, 'request': <AsgiRequest: GET '/'>, 'user': <SimpleLazyObject: <function AuthenticationMiddleware.process_request.<locals>.<lambda> at 0x7ff4f6ac38c8>>, 'perms': <django.contrib.auth.context_processors.PermWrapper object at 0x7ff4fd7497f0>, 'messages': <django.contrib.messages.storage.fallback.FallbackStorage object at 0x7ff4f6bdfdd8>, 'DEFAULT_MESSAGE_LEVELS': {'DEBUG': 10, 'INFO': 20, 'SUCCESS': 25, 'WARNING': 30, 'ERROR': 40}}, {}, {'paginator': <django.core.paginator.Paginator object at 0x7ff4f6b3cc50>, 'page_obj': <Page 1 of 1>, 'is_paginated': False, 'object_list': <QuerySet [<Post: First Announcement>]>, 'posts': <QuerySet [<Post: First Announcement>]>, 'view': <blog.views.PostListView object at 0x7ff4f6bdf438>}]
(0.000) SELECT "django_session"."session_key", "django_session"."session_data", "django_session"."expire_date" FROM "django_session" WHERE ("django_session"."expire_date" > '2019-04-24 16:07:05.790303' AND "django_session"."session_key" = 'bxpt7g6j9sufe1f4vdvfcmhqcijixtqx'); args=('2019-04-24 16:07:05.790303', 'bxpt7g6j9sufe1f4vdvfcmhqcijixtqx')
(0.000) SELECT "users_user"."id", "users_user"."password", "users_user"."last_login", "users_user"."is_superuser", "users_user"."username", "users_user"."first_name", "users_user"."last_name", "users_user"."email", "users_user"."is_staff", "users_user"."is_active", "users_user"."date_joined", "users_user"."phone_number", "users_user"."role", "users_user"."institution_id" FROM "users_user" WHERE "users_user"."id" = 1; args=(1,)
(0.000) SELECT "institutions_institution"."id", "institutions_institution"."name", "institutions_institution"."abbreviation", "institutions_institution"."city_id", "institutions_institution"."met", "institutions_institution"."moc", "institutions_institution"."ethics", "institutions_institution"."status_request", "institutions_institution"."is_private", "institutions_institution"."ri_1_tools", "institutions_institution"."general", "institutions_institution"."role", "institutions_institution"."type_of_inst", "institutions_institution"."student_count", "institutions_institution"."staff_count", "institutions_institution"."internet_access", "institutions_institution"."online", "institutions_institution"."guest_lectures", "institutions_institution"."environment", "institutions_institution"."focus_pst", "institutions_institution"."further", "institutions_institution"."school_size", "institutions_institution"."community_size", "institutions_institution"."girl_ratio", "institutions_institution"."qualifications", "institutions_institution"."percent_indigenous", "institutions_institution"."age" FROM "institutions_institution" WHERE "institutions_institution"."id" = 1; args=(1,)
(0.000) SELECT "blog_post"."id", "blog_post"."title", "blog_post"."content", "blog_post"."date_posted", "blog_post"."date_expired", "blog_post"."author_id", "blog_post"."fileAttachment", "blog_post"."imageAttachment" FROM "blog_post" ORDER BY "blog_post"."date_posted" DESC  LIMIT 1; args=()
(0.000) SELECT "users_user"."id", "users_user"."password", "users_user"."last_login", "users_user"."is_superuser", "users_user"."username", "users_user"."first_name", "users_user"."last_name", "users_user"."email", "users_user"."is_staff", "users_user"."is_active", "users_user"."date_joined", "users_user"."phone_number", "users_user"."role", "users_user"."institution_id" FROM "users_user" WHERE "users_user"."id" = 1; args=(1,)
[mHTTP GET / 200 [0.02, 127.0.0.1:56762][0m
[mHTTP GET /static/blog/main.css 200 [0.00, 127.0.0.1:56762][0m
